<?xml version="1.0"?>
<!-- Open_Manipulator Chain -->
<robot xmlns:xacro="http://ros.org/wiki/xacro">

  <xacro:macro name="Supp_Link" params="link_number x y z">
    <link name="supp_link${link_number}">
      <visual>
        <origin xyz="0 0 0" rpy="-1.57 0 0"/>
        <geometry>
          <cylinder radius="0.04" length="0.04"/>
        </geometry>
      </visual>
      <inertial>
        <origin xyz="0 0 0" />
        <mass value="9.8406837e-03" />
        <inertia ixx="3.4543422e-06" ixy="-1.6031095e-07" ixz="-3.8375155e-08"
                 iyy="3.2689329e-06"  iyz="2.8511935e-07"
                 izz="1.8850320e-06" />
      </inertial>
    </link>
    <joint name="supp_joint${link_number}" type="fixed">
      <parent link="link${link_number}"/>
      <child link="supp_link${link_number}"/>
      <origin xyz="${x} ${y} ${z}" rpy="0 0 0"/>
    </joint>
  </xacro:macro>


  <!-- Link 1 -->
  <link name="link1">
    <visual>
      <origin xyz="0.0 0.0 0.090" rpy="0 0 0"/>
      <geometry>
        <cylinder radius="0.10" length="0.180"/>
      </geometry>
      <material name="black"/>
    </visual>

    <collision>
      <origin xyz="0.0 0.0 0.090" rpy="0 0 0"/>
      <geometry>
        <box size="0.240 0.340 0.180"/>
      </geometry>
    </collision>

    <inertial>
      <origin xyz="3.0876154e-04 0.0000000e+00 -1.2176461e-04" />
      <mass value="7.9119962e-02" />
      <inertia ixx="1.2505234e-05" ixy="0.0" ixz="-1.7855208e-07"
               iyy="2.1898364e-05" iyz="0.0"
               izz="1.9267361e-05" />
    </inertial>
  </link>

  <!-- Joint 1 -->
  <joint name="joint1" type="revolute">
    <parent link="link1"/>
    <child link="link2"/>
    <origin xyz="0.0 0.0 0.200" rpy="0 0 0"/>
    <axis xyz="0 0 1"/>
    <limit velocity="4.8" effort="1" lower="${-pi*0.9}" upper="${pi*0.9}"/> 
    <!-- <limit velocity="4.8" effort="1" lower="${-pi/2}" upper="${pi/2}" /> -->
  </joint>

  <!--  Link 2 -->
  <link name="link2">
    <visual>
      <origin xyz="0 0 0.005" rpy="0 0 0"/>
      <geometry>
        <cylinder radius="0.050" length="0.010"/>
      </geometry>
      <material name="black"/>
    </visual>

    <collision>
      <origin xyz="0 0 0.005" rpy="0 0 0"/>
      <geometry>
        <cylinder radius="0.050" length="0.010"/>
      </geometry>
    </collision>

    <inertial>
      <origin xyz="-3.0184870e-04 5.4043684e-04 ${0.018 + 2.9433464e-02}" />
      <mass value="9.8406837e-02" />
      <inertia ixx="3.4543422e-05" ixy="-1.6031095e-08" ixz="-3.8375155e-07"
               iyy="3.2689329e-05" iyz="2.8511935e-08"
               izz="1.8850320e-05" />
    </inertial>
  </link>

  <!--  Joint 2 -->
  <joint name="joint2" type="revolute">
    <parent link="link2"/>
    <child link="link3"/>
    <origin xyz="0.0 0.0 0.040" rpy="0 0 0"/>
    <axis xyz="0 1 0"/>
    <!-- <limit velocity="4.8" effort="1" lower="${-pi*0.57}" upper="${pi*0.5}" /> -->
    <limit velocity="4.8" effort="1" lower="${-pi/2}" upper="${0.3}" />
  </joint>

  <xacro:Supp_Link link_number="3" x="0" y="0" z="0.420"/>

  <!--  Link 3 -->
  <link name="link3">
    <visual>
      <origin xyz="0 0 0.200" rpy="0 0 0"/>
      <geometry>
        <box size="0.040 0.040 0.400"/>
      </geometry>
      <material name="black"/>
    </visual>

    <collision>
      <origin xyz="0 0 0.200" rpy="0 0 0"/>
      <geometry>
        <box size="0.040 0.040 0.400"/>
      </geometry>
    </collision>

    <inertial>
      <origin xyz="1.0308393e-02 3.7743363e-04 1.0170197e-01" />
      <mass value="1.3850917e-01" />
      <inertia ixx="3.3055381e-04" ixy="-9.7940978e-08" ixz="-3.8505711e-05"
               iyy="3.4290447e-04" iyz="-1.5717516e-06"
               izz="6.0346498e-05" />
    </inertial>
  </link>

  <!--  Joint 3 -->
  <joint name="joint3" type="revolute">
    <parent link="link3"/>
    <child link="link4"/>
    <origin xyz="0.0 0.0 0.420" rpy="0 0 0"/>
    <axis xyz="0 1 0"/>
    <limit velocity="4.8" effort="1" lower="${-pi*0.3}" upper="${pi*0.44}" />
    <!-- <limit velocity="4.8" effort="1" lower="${-pi}" upper="${pi}" /> -->
  </joint>

  <xacro:Supp_Link link_number="4" x="0.220" y="0" z="0"/>

  <!--  Link 4 -->
  <link name="link4">
    <visual>
      <origin xyz="0.105 0 0" rpy="0 0 0"/>
      <geometry>
        <box size="0.170 0.040 0.040"/>
      </geometry>
      <material name="black"/>
    </visual>

    <collision>
      <origin xyz="0.105 0 0" rpy="0 0 0"/>
      <geometry>
        <box size="0.170 0.040 0.040"/>
      </geometry>
    </collision>

    <inertial>
      <origin xyz="9.0909590e-02 3.8929816e-04 2.2413279e-04" />
      <mass value="1.3274562e-01" />
      <inertia ixx="3.0654178e-05" ixy="-1.2764155e-06" ixz="-2.6874417e-07"
               iyy="2.4230292e-04" iyz="1.1559550e-08"
               izz="2.5155057e-04" />
    </inertial>
  </link>

  <!--  Joint 4 -->
  <joint name="joint4" type="revolute">
    <parent link="link4"/>
    <child link="link5"/>
    <origin xyz="0.210 0.0 0.0" rpy="0 0 0"/>
    <axis xyz="0 1 0"/>
    <limit velocity="4.8" effort="1" lower="${-pi*0.57}" upper="${pi*0.65}" />
    <!-- <limit velocity="4.8" effort="1" lower="${-pi}" upper="${pi}" /> -->
  </joint>

  <!--  Link 5 -->
  <link name="link5">
    <visual>
      <origin xyz="0 0 -0.170" rpy="0 0 0"/>
      <geometry>
        <cylinder radius="0.040" length="0.100"/>
      </geometry>
      <material name="black"/>
    </visual>

    <collision>
      <origin xyz="0 0 -0.170" rpy="0 0 0"/>
      <geometry>
        <box size="0.040 0.040 0.300"/>
      </geometry>
    </collision>

    <inertial>
      <origin xyz="4.4206755e-02 3.6839985e-07 8.9142216e-03" />
      <mass value="1.4327573e-01" />
      <inertia ixx="8.0870749e-05" ixy="0.0" ixz="-1.0157896e-06"
               iyy="7.5980465e-05" iyz="0.0"
               izz="9.3127351e-05" />
    </inertial>
  </link>

  <!-- end effector joint -->
  <joint name="end_effector_joint" type="continuous">
    <origin xyz="0.0 0.0 -0.400" rpy="0 0 0"/>
    <parent link="link5"/>
    <child link="end_effector_link"/>
    <axis xyz="0 0 1"/>
    <limit velocity="1" effort="0.1" />
  </joint>

  <!-- end effector link -->
  <link name="end_effector_link">
    <visual>
      <origin xyz="0 0 0" rpy="0 0 0"/>
      <geometry>
        <box size="0.01 0.01 0.01"/>
      </geometry>
      <material name="red"/>
     </visual>

    <inertial>
      <origin xyz="0 0 0" />
      <mass value="1.0e-03" />
      <inertia ixx="1.0e-03" ixy="0.0" ixz="0.0"
               iyy="1.0e-03" iyz="0.0"
               izz="1.0e-03" />
    </inertial>
  </link>

  
</robot>




